# 错误处理与测试
go不能抛异常，但有一套`defer-panic-and-recover`机制。

普通错误(error)：在函数和方法中返回错误对象作为它们的唯一或最后一个返回值——如果返回 nil，则没有错误发生——并且主调（calling）函数总是应该检查收到的错误。

```go
if value, err := pack1.Func1(param1); err != nil {
	fmt.Printf("Error %s in pack1.Func1 with parameter %v", err.Error(), param1)
	return    // or: return err
} else {
	// Process(value)
}
```

`panic and recover` 是用来处理真正的异常（无法预测的错误）而不是普通的错误。

# 错误处理

Go 有一个预先定义的 error 接口类型

```go
type error interface {
	Error() string
}
```

## 定义错误

使用`errors.New` 函数接收合适的错误信息来创建错误变量

```go
err := errors.New("math - square root of negative number")
```

错误结构类型，实现`Error`方法：
```go
// PathError records an error and the operation and file path that caused it.
type PathError struct {
	Op string    // "open", "unlink", etc.
	Path string  // The associated file.
	Err error  // Returned by the system call.
}

func (e *PathError) Error() string {
	return e.Op + " " + e.Path + ": "+ e.Err.Error()
}
```

错误类型以 “Error” 结尾，错误变量以 “err” 或 “Err” 开头。
## 用 fmt 创建错误对象
要返回包含错误参数的更有信息量的字符串，例如：可以用 `fmt.Errorf()` 来实现。和打印信息不同的是它用信息**生成错误对象**。

```go
if f < 0 {
	return 0, fmt.Errorf("math: square root of negative number %g", f)
}
```

# 运行时异常和panic
当发生像数组下标越界或类型断言失败这样的运行错误时，Go 运行时会触发*运行时 panic*，伴随着程序的崩溃抛出一个 `runtime.Error` 接口类型的值。这个错误值有个 `RuntimeError()` 方法用于区别普通错误。

`panic` 可以直接从代码初始化：当错误条件（我们所测试的代码）很严苛且不可恢复，程序不能继续运行时，可以使用 `panic` 函数产生一个中止程序的运行时错误。`panic` 接收一个做任意类型的参数，通常是字符串，在程序死亡时被打印出来。Go 运行时负责中止程序并给出调试信息。

[panic.go](examples/chapter_13/panic.go) 
```go
package main

import "fmt"

func main() {
	fmt.Println("Starting the program")
	panic("A severe error occurred: stopping the program!")
	fmt.Println("Ending the program")
}
```

输出如下：

```
Starting the program
panic: A severe error occurred: stopping the program!
panic PC=0x4f3038
runtime.panic+0x99 /go/src/pkg/runtime/proc.c:1032
       runtime.panic(0x442938, 0x4f08e8)
main.main+0xa5 E:/Go/GoBoek/code examples/chapter 13/panic.go:8
       main.main()
runtime.mainstart+0xf 386/asm.s:84
       runtime.mainstart()
runtime.goexit /go/src/pkg/runtime/proc.c:148
       runtime.goexit()
---- Error run E:/Go/GoBoek/code examples/chapter 13/panic.exe with code Crashed
---- Program exited with code -1073741783
```

一个检查程序是否被已知用户启动的具体例子：

```go
var user = os.Getenv("USER")

func check() {
	if user == "" {
		panic("Unknown user: no value for $USER")
	}
}
```

可以在导入包的 init() 函数中检查这些。

当发生错误必须中止程序时，`panic` 可以用于错误处理模式：

```go
if err != nil {
	panic("ERROR occurred:" + err.Error())
}
```

**Go panicking**：

在多层嵌套的函数调用中调用 panic，可以马上中止当前函数的执行，所有的 defer 语句都会保证执行并把控制权交还给接收到 panic 的函数调用者。

向上冒泡直到最顶层，并执行（每层的）defer，在栈顶处程序崩溃，并在命令行中用传给 panic 的值报告错误的这个终止过程叫 *panicking*。

标准库中有许多包含 `Must` 前缀的函数，像 `regexp.MustComplie` 和 `template.Must`；当正则表达式或模板中转入的转换字符串导致错误时，这些函数会 panic。

不能随意地用 panic 中止程序，必须尽力补救错误让程序能继续执行。

# 从panic中恢复(recover)
内建函数recover用于从panic或错误场景中恢复：让程序可以从 panicking 重新获得控制权，停止终止过程进而恢复正常执行。

`recover` 只能在 defer 修饰的函数中使用：用于取得 panic调用中传递过来的错误值，如果程序正常执行，调用 `recover` 会返回 nil。

**panic 会导致栈被展开直到 defer 修饰的 recover() 被调用或者程序中止。**

下面例子中的 protect 函数调用函数参数 g 来保护调用者防止从 g 中抛出的运行时 panic，并展示 panic 中的信息：

```go
func protect(g func()) {
	defer func() {
		log.Println("done")
		// Println executes normally even if there is a panic
		if err := recover(); err != nil {
			log.Printf("run time panic: %v", err)
		}
	}()
	log.Println("start")
	g() //   possible runtime-error
}
```

[panic_recover.go](examples/chapter_13/panic_recover.go)：

```go
// panic_recover.go
package main

import (
	"fmt"
)

func badCall() {
	panic("bad end")
}

func test() {
	defer func() {
		if e := recover(); e != nil {
			fmt.Printf("Panicing %s\r\n", e)
		}
	}()
	badCall()
	fmt.Printf("After bad call\r\n") // <-- would not reach
}

func main() {
	fmt.Printf("Calling test\r\n")
	test()
	fmt.Printf("Test completed\r\n")
}
```

输出：

```
Calling test
Panicing bad end
Test completed
```

# 自定义包中的错误处理和panicking
这是所有自定义包实现者应该遵守的最佳实践：

1）*在包内部，总是应该从 panic 中 recover*：不允许显式的超出包范围的 panic()

2）*向包的调用者返回错误值（而不是 panic）。*

在包内部，特别是在非导出函数中有很深层次的嵌套调用时，将 panic 转换成 error 来告诉调用方为何出错，是很实用的（且提高了代码可读性）。

 [parse.go](examples/chapter_13/parse/parse.go)
```go
// parse.go
package parse

import (
	"fmt"
	"strconv"
	"strings"
)

// A ParseError indicates an error in converting a word into an integer.
type ParseError struct {
	Index int    // The index into the space-separated list of words.
	Word  string // The word that generated the parse error.
	Err   error  // The raw error that precipitated this error, if any.
}

//Error和String方法同时实现时，fmt优先调用Error

// String returns a human-readable error message.
func (e *ParseError) Error() string {
	return fmt.Sprintf("Error() pkg parse: error parsing %q as int", e.Word)
}

func (e *ParseError) String() string {
	return fmt.Sprintf("Stirng() pkg parse: error parsing %q as int", e.Word)
}

// Parse parses the space-separated words in in put as integers.
func Parse(input string) (numbers []int, err error) {
	defer func() {
		if r := recover(); r != nil {
			var ok bool
			//类型断言
			err, ok = r.(error)
			if !ok {
				err = fmt.Errorf("pkg: %v", r)
			}
		}
	}()

	fields := strings.Fields(input)
	numbers = fields2numbers(fields)
	return
}

func fields2numbers(fields []string) (numbers []int) {
	if len(fields) == 0 {
		panic("no words to parse")
	}
	for idx, field := range fields {
		num, err := strconv.Atoi(field)
		if err != nil {
			//panic可以接受任意类型的参数
			panic(&ParseError{idx, field, err})
		}
		numbers = append(numbers, num)
	}
	return
}
```

[panic_package.go](examples/chapter_13/panic_package.go)

```go
// panic_package.go
package main

import (
	"fmt"
	"./parse/parse"
)

func main() {
    var examples = []string{
            "1 2 3 4 5",
            "100 50 25 12.5 6.25",
            "2 + 2 = 4",
            "1st class",
            "",
    }

    for _, ex := range examples {
        fmt.Printf("Parsing %q:\n  ", ex)
        nums, err := parse.Parse(ex)
        if err != nil {
            fmt.Println(err) // here String() method from ParseError is used
            continue
        }
        fmt.Println(nums)
    }
}
```

输出：

```
Parsing "1 2 3 4 5":
  [1 2 3 4 5]
Parsing "100 50 25 12.5 6.25":
  pkg: pkg parse: error parsing "12.5" as int
Parsing "2 + 2 = 4":
  pkg: pkg parse: error parsing "+" as int
Parsing "1st class":
  pkg: pkg parse: error parsing "1st" as int
Parsing "":
  pkg: no words to parse
```
# 一种用闭包处理错误的模式

[panic_defer.go](exercises/chapter_13/panic_defer.go)
```go
// panic_defer.go
package main

import "fmt"

func main() {
	f()
	fmt.Println("Returned normally from f.")
}

func f() {
	defer func() {
		if r := recover(); r != nil {
			fmt.Println("Recovered in f", r)
		}
	}()
	fmt.Println("Calling g.")
	g(0)
	fmt.Println("Returned normally from g.")
}

func g(i int) {
	if i > 3 {
		fmt.Println("Panicking!")
		panic(fmt.Sprintf("%v", i))
	}
	defer fmt.Println("Defer in g", i)
	fmt.Println("Printing in g", i)
	g(i + 1)
}
```
```
Calling g.
Printing in g 0
Printing in g 1
Printing in g 2
Printing in g 3
panicking



```
# 启动外部命令和程序
# go中单元测试和基准测试
# 测试例子
# 用测试表驱动测试
# 性能调试